<mujoco model="Humanoid" >
  <compiler angle="radian" meshdir="../assets/meshes"/>
  <visual>
    <global offwidth="1920" offheight="1080"/>
  </visual>

<default>
  <joint frictionloss="0.1"/>  <!-- All joints get this by default -->
  
  <default class="motor">
    <joint damping="0.5"/> 
  </default>
  
  <default class="visual">
    <geom material="visual_grey" contype="0" conaffinity="0" group="2"/>
  </default>
  
  <default class="collision">
    <geom material="collision_grey" condim="3" contype="0" conaffinity="1" group="1"/>
  </default>
</default>



  <asset>
    <!-- Add these material definitions -->
    <material name="visual_grey" rgba="0.7 0.7 0.7 1.0" />
    <material name="collision_grey" rgba="0.5 0.5 0.5 0.5" />
    <texture type="skybox" builtin="flat" rgb1="0 0 0" rgb2="0 0 0" width="512" height="3072"/>
    <texture type="2d" name="groundplane" builtin="checker" mark="edge" rgb1="0.2 0.3 0.4" rgb2="0.1 0.2 0.3" markrgb="0.8 0.8 0.8" width="300" height="300"/>
    <material name="groundplane" texture="groundplane" texuniform="true" texrepeat="5 5" reflectance="0.2"/>
    <texture type="skybox" builtin="gradient" rgb1="0.3 0.5 0.7" rgb2="0 0 0" width="512" height="512"/>
    <texture name="texplane" type="2d" builtin="checker" rgb1=".2 .3 .4" rgb2=".1 0.15 0.2" width="512" height="512" mark="cross" markrgb=".8 .8 .8"/>
    <material name="material" rgba="0.75294 0.75294 0.75294 1" />
    <material name="collision_material" rgba="1.0 0.28 0.1 0.9" />
    <mesh name="pelvis_link" file="base_link.stl" />
    <mesh name="left_hip_pitch_link" file="left_hip_pitch_link.stl" />
    <mesh name="left_hip_roll_link" file="left_hip_roll_link.stl" />
    <mesh name="left_hip_yaw_link" file="left_hip_yaw_link.stl" />
    <mesh name="left_knee_link" file="left_knee_link.stl" />
    <mesh name="left_foot1_link" file="left_foot1_link.stl" />
    <mesh name="left_foot2_link" file="left_foot2_link.stl" />
    <mesh name="left_ankle1_link"  file="left_ankle1_link.stl"/>
    <mesh name="left_ankle2_link"  file="left_ankle2_link.stl"/>    
    <mesh name="right_hip_pitch_link" file="right_hip_pitch_link.stl" />
    <mesh name="right_hip_roll_link" file="right_hip_roll_link.stl" />
    <mesh name="right_hip_yaw_link" file="right_hip_yaw_link.stl" />
    <mesh name="right_knee_link" file="right_knee_link.stl" />
    <mesh name="right_foot1_link" file="right_foot1_link.stl" />
    <mesh name="right_foot2_link" file="right_foot2_link.stl" />
    <mesh name="right_ankle1_link"  file="right_ankle1_link.stl"/>
   <mesh name="right_ankle2_link"  file="right_ankle2_link.stl"/>
   <mesh name="torso_link"  file="torso_link.stl"/>
   <mesh name="waist_roll_link"  file="waist_roll_link.stl"/>
   <mesh name="waist_pitch_link"  file="waist_pitch_link.stl"/>
   <mesh name="chest_link"  file="chest_link.stl"/>
   <mesh name="left_shoulder_pitch_link"  file="left_shoulder_pitch_link.stl"/>
   <mesh name="left_shoulder_roll_link"  file="left_shoulder_roll_link.stl"/>
   <mesh name="left_elbow_yaw_link"  file="left_elbow_yaw_link.stl"/>
   <mesh name="left_elbow_forearm_yaw_link"  file="left_elbow_forearm_yaw_link.stl"/>
   <mesh name="left_wrist_yaw_link"  file="left_wrist_yaw_link.stl"/>
   <mesh name="right_shoulder_pitch_link"  file="right_shoulder_pitch_link.stl"/>
   <mesh name="right_shoulder_roll_link"  file="right_shoulder_roll_link.stl"/>
   <mesh name="right_elbow_yaw_link"  file="right_elbow_yaw_link.stl"/>
   <mesh name="right_elbow_forearm_yaw_link"  file="right_elbow_forearm_yaw_link.stl"/>
   <mesh name="right_wrist_yaw_link"  file="right_wrist_yaw_link.stl"/>
   <mesh name="neck_link"  file="neck_link.stl"/>
   <mesh name="neck_yaw_link"  file="neck_yaw_link.stl"/>
   <mesh name="head_link"  file="head_link.stl"/>
   <mesh name="camera_link"  file="camera_link.stl"/>
   <mesh name="waist_rod_link"  file="waist_rod_link.stl"/> 
  </asset>

  <worldbody>
    <light pos="1 0 3.5" dir="0 0 -1" directional="true"/>
    <geom name="floor" size="0 0 0.05" type="plane" material="groundplane"/>
    <light directional="true" diffuse=".4 .4 .4" specular="0.1 0.1 0.1" pos="0 0 5.0" dir="0 0 -1" castshadow="false" />
    <light directional="true" diffuse=".6 .6 .6" specular="0.2 0.2 0.2" pos="0 0 4" dir="0 0 -1" />

    <body name="pelvis_link" pos="0 0 0.68" quat="1 0 0 0 "> 
      <inertial pos="0.00011927 -0.053041 0.11817" mass="0.85358" diaginertia="0.000753949 0.000519781 0.0005022"/>
      <joint name="floating_base_joint" type="free" limited="false" actuatorfrclimited="false"/>
      <geom name="pelvis_link_collision" pos="0 0 0" quat="1.0 0.0 0.0 0.0" type="mesh" mesh="pelvis_link"/>
      <geom name="pelvis_link_visual" pos="0 0 0" quat="1.0 0.0 0.0 0.0" type="mesh" mesh="pelvis_link" class="visual" />
      <site name="imu_in_pelvis" size="0.01" pos="0.00011927 -0.053041 0.11817"/>

      <body name="left_hip_pitch_link"  pos="0 0 0" >

        <joint name="left_hip_pitch_joint" type="hinge" ref="0.0" class="motor" range="-2.094395 1" axis="0 0.70711 -0.70711" armature="0.0652"/>
        <inertial pos="-0.0076949 0.035164 -0.00056716" quat="0.992601 0.11621 0.00969005 0.0338305" mass="1.5469" diaginertia="0.00288379 0.00207112 0.00197599"/>
        <geom name="left_hip_pitch_link_collision" pos="0 0 0" quat="1.0 0.0 0.0 0.0" type="mesh" mesh="left_hip_pitch_link" class="collision" />
        <geom name="left_hip_pitch_link_visual" pos="0 0 0" quat="1.0 0.0 0.0 0.0" type="mesh" mesh="left_hip_pitch_link" class="visual" />

        <body name="left_hip_roll_link" pos="0.0239754 0.075629 -0.000417045" quat="1 0 0 0.000162606">
          <joint name="left_hip_roll_joint" type="hinge" ref="0.0" class="motor" range="-0.785398 0.785398" axis="1 0 0" armature="0.100"/>

          <inertial pos="-0.034577 0.0013532 -0.074963" quat="0.999252 0.00719015 -0.0379915 -0.000173782" mass="0.84068" diaginertia="0.00165655 0.00129023 0.00112671"/>
          <geom name="left_hip_roll_link_collision" pos="0 0 0" quat="1.0 0.0 0.0 0.0" type="mesh" mesh="left_hip_roll_link" class="collision" />
          <geom name="left_hip_roll_link_visual" pos="0 0 0" quat="1.0 0.0 0.0 0.0"  type="mesh" mesh="left_hip_roll_link" class="visual" />
          <body name="left_hip_yaw_link"  pos="-0.024 0.00265744 -0.175268" quat="0.999979 0.00648448 0 0">

            <joint name="left_hip_yaw_joint" type="hinge" ref="0.0" class="motor" range="-0.785398 0.785398" axis="0 0 -1" armature="0.0343"/>
            <inertial pos="5.3998e-05 0.0016007 -0.02388" quat="0.498266 0.501877 0.498624 0.501222" mass="1.0856" diaginertia="0.00105081 0.000856783 0.00071265"/>
            <geom name="left_hip_yaw_link_collision" pos="0 0 0" quat="1.0 0.0 0.0 0.0" type="mesh" mesh="left_hip_yaw_link" class="collision" />
            <geom name="left_hip_yaw_link_visual" pos="0 0 0" quat="1.0 0.0 0.0 0.0"  type="mesh" mesh="left_hip_yaw_link" class="visual" />
          
            <body name="left_knee_link" pos="0.000417045 0.0285 -0.133921">
              <joint name="left_knee_joint" type="hinge" ref="0.0" class="motor" range="0 1.5" axis="0 1 0" armature="0.0330"/>
              <inertial pos="0.00377987 -0.0312987 -0.105632" quat="0.671945 -0.0508905 0.00714861 0.738816" mass="2.00553" diaginertia="0.00944072 0.00929183 0.00158368"/>
              <geom name="left_knee_link_collision" pos="0 0 0" quat="1.0 0.0 0.0 0.0" type="mesh" mesh="left_knee_link" class="collision" />
              <geom name="left_knee_link_visual" pos="0 0 0" quat="1.0 0.0 0.0 0.0"  type="mesh" mesh="left_knee_link" class="visual" />
              <geom name="left_ankle1_link_collision" pos="0.034083 -0.0285 -0.10537" quat="1 0 0 0" type="mesh"  mesh="left_ankle1_link" class="collision" />
              <geom name="left_ankle1_link_visual" pos="0.034083 -0.0285 -0.10537" quat="1 0 0 0" type="mesh"  mesh="left_ankle1_link" class="visual" />              
              <geom name="left_ankle2_link_visual" pos="0.034083 -0.0285 -0.169879"  type="mesh"  mesh="left_ankle2_link" class="visual"/>
              <body name="left_foot1_link" pos="-0.000417045 -0.0435 -0.318879">


                <joint name="left_foot1_joint" type="hinge" ref="0.0" class="motor" range="-0.349066 0.5" axis="0 1 0" armature="0.0236"/>
                <inertial pos="0.028298 0.0146625 -0.026002" quat="0.00408055 0.752967 0.00332422 0.658037" mass="0.23579" diaginertia="0.00304354 0.00283597 0.000667818"/>
                <geom name="left_foot1_link_collision" pos="0 0 0" quat="1.0 0.0 0.0 0.0" type="mesh" mesh="left_foot1_link" class="collision" />
                <geom name="left_foot1_link_visual" pos="0 0 0" quat="1.0 0.0 0.0 0.0"  type="mesh" mesh="left_foot1_link" class="visual" />
                <body name="left_foot2_link" pos="-0.02 0.015 0">

                  <joint name="left_foot2_joint" type="hinge" ref="0.0" class="motor" range="-0.1 0.1" axis="-1 0 0" armature="0.0236"/>
                  <inertial pos="0.057204 -0.00036388 -0.033983" quat="0.00465825 0.720924 0.00447622 0.692984" mass="0.76036" diaginertia="0.00266592 0.00232824 0.000447017"/>
                  <geom name="left_foot2_link_collision" pos="0 0 0" quat="1.0 0.0 0.0 0.0" type="mesh" mesh="left_foot2_link" class="collision" />
                  <geom name="left_foot2_link_visual" pos="0 0 0" quat="1.0 0.0 0.0 0.0"  type="mesh" mesh="left_foot2_link" class="visual" />

                    <site name="left_foot" pos="0.04 0 -0.025"/>

                </body>
              </body>
            </body>
          </body>
        </body>
      </body>
      <body name="right_hip_pitch_link" pos="4.16270248897038E-05 -0.127999993231209 0">
        <inertial pos="-0.0076883 -0.03517 0.00056004" quat="0.992712 0.115309 -0.00964744 -0.0336693" mass="1.5469" diaginertia="0.00288375 0.00207107 0.00197607"/>
        <joint name="right_hip_pitch_joint" type="hinge" ref="0.0" class="motor" range="-1 2.094395" axis="0 -0.70711 -0.70711" armature="0.0652"/>
        <geom name="right_hip_pitch_link_collision" pos="0 0 0" quat="1.0 0.0 0.0 0.0" type="mesh" mesh="right_hip_pitch_link" class="collision" />
        <geom name="right_hip_pitch_link_visual" pos="0 0 0" quat="1.0 0.0 0.0 0.0"  type="mesh" mesh="right_hip_pitch_link" class="visual" />
        <body name="right_hip_roll_link" pos="0.0202 -0.076 0" quat="1 0 0 0.000162606">
          <joint name="right_hip_roll_joint" type="hinge" ref="0.0" class="motor" range="-0.785398 0.785398" axis="1 0 0" armature="0.100"/>
          <inertial pos="-0.032145 -3.7396e-06 -0.063538" quat="0.999474 -7.01093e-07 -0.0324354 2.16037e-05" mass="0.7444" diaginertia="0.00155531 0.001194 0.000935294"/>
          <geom name="right_hip_roll_link_collision" pos="0 0 0" quat="1.0 0.0 0.0 0.0" type="mesh" mesh="right_hip_roll_link" class="collision" />
          <geom name="right_hip_roll_link_visual" pos="0 0 0" quat="1.0 0.0 0.0 0.0"  type="mesh" mesh="right_hip_roll_link" class="visual" />
          <body name="right_hip_yaw_link" pos="-0.0202000000000037 0 -0.1757" quat="0.999979 0.00648448 0 0">
            <joint name="right_hip_yaw_joint" type="hinge" ref="0.0" class="motor" range="-0.785398 0.785398" axis="0 0 -1" armature="0.0343"/>
            <inertial pos="-2.7827e-05 -0.0016262 -0.02388" quat="0.501873 0.49827 0.501286 0.498561" mass="1.0856" diaginertia="0.00105081 0.000856782 0.00071265"/>
            <geom name="right_hip_yaw_link_collision" pos="0 0 0" quat="1.0 0.0 0.0 0.0" type="mesh" mesh="right_hip_yaw_link" class="collision" />
            <geom name="right_hip_yaw_link_visual" pos="0 0 0" quat="1.0 0.0 0.0 0.0"  type="mesh" mesh="right_hip_yaw_link" class="visual" />
            <body name="right_knee_link" pos="0 -0.0247000000000758 -0.134300000000004">
              <joint name="right_knee_joint" type="hinge" ref="0.0" class="motor" range="-1.5 0" axis="0 -1 0" armature="0.0330"/>
              <inertial pos="0.00018686274200333 0.0273157431367975 -0.0975490194978977" quat="0.73938 0.00727448 -0.0507906 0.67133" mass="1.68479653824874" diaginertia="0.00943616 0.00928693 0.00158256"/>
              <geom name="right_knee_link_collision" pos="0 0 0" quat="1.0 0.0 0.0 0.0" type="mesh" mesh="right_knee_link" class="collision" />
              <geom name="right_knee_link_visual" pos="0 0 0" quat="1.0 0.0 0.0 0.0"  type="mesh" mesh="right_knee_link" class="visual" />
              <geom name="right_ankle1_link_collision" pos="0.0375 0.0247 -0.105" quat="1 0 0 0" type="mesh" rgba="0.64706 0.61961 0.58824 1" mesh="right_ankle1_link" class="collision" />
              <geom name="right_ankle1_link_visual" pos="0.0375 0.0247 -0.105" quat="1 0 0 0" type="mesh" rgba="0.64706 0.61961 0.58824 1" mesh="right_ankle1_link" class="visual" />
              <geom name="right_ankle2_link_collision" pos="0.0375 0.0247 -0.1695" quat="1 0 0 0" type="mesh" rgba="0.64706 0.61961 0.58824 1" mesh="right_ankle2_link" class="collision" />
              <geom name="right_ankle2_link_visual" pos="0.0375 0.0247 -0.1695" quat="1 0 0 0" type="mesh" rgba="0.64706 0.61961 0.58824 1" mesh="right_ankle2_link" class="visual" />
              <body name="right_foot1_link" pos="0 0.297852075295849 -0.3186416753026" quat="0.999979 0.00648448 0 0">
                <joint name="right_foot1_joint" type="hinge" ref="0.0" class="motor" range="-0.5 0.349066" axis="0 -1 0" armature="0.0236"/>
                <inertial pos="3.1564e-09 -0.27313 0.0036841" quat="0.5 0.5 -0.5 0.5" mass="0.23579" diaginertia="9.08977e-05 5.10453e-05 5.1045e-05"/>
                <geom name="right_foot1_link_collision" pos="0 0 0" quat="1.0 0.0 0.0 0.0" type="mesh" mesh="right_foot1_link" class="collision" />
                <geom name="right_foot1_link_visual" pos="0 0 0" quat="1.0 0.0 0.0 0.0"  type="mesh" mesh="right_foot1_link" class="visual" />
                <body name="right_foot2_link" pos="-0.0199999999999545 -0.273127266729484 0.0036840845761229" quat="0.999979 -0.00648448 0 0">
                  <joint name="right_foot2_joint" type="hinge" ref="0.0" class="motor" range="-0.1 0.1" axis="-1 0 0" armature="0.0236"/>
                  <inertial pos="0.057171 -1.693e-09 -0.034065" quat="0 0.720938 0 0.693" mass="0.75781" diaginertia="0.00266586 0.002328 0.000446697"/>
                  <geom name="right_foot2_link_collision" pos="0 0 0" quat="1.0 0.0 0.0 0.0" type="mesh" mesh="right_foot2_link" class="collision" />
                  <geom name="right_foot2_link_visual" pos="0 0 0" quat="1.0 0.0 0.0 0.0"  type="mesh" mesh="right_foot2_link" class="visual" />

                    <site name="right_foot" pos="0.04 0 -0.025"/>

                </body>
              </body>
            </body>
          </body>
        </body>
        
      </body>
      <site name="pelvis_link_site" pos="0 0 0" quat="1 0 0 0" />
      <camera name="front_camera" mode="track" fovy="90.0" quat="4.329780281177467e-17 4.329780281177466e-17 0.7071067811865475 0.7071067811865476" pos="0.0 2.0 0.5" />
      <camera name="side_camera" mode="track" fovy="90.0" quat="-0.5 -0.4999999999999999 0.5 0.5000000000000001" pos="-2.0 0.0 0.5" />
    </body>
  </worldbody>

  <actuator>
    <motor name="left_hip_pitch_joint_ctrl" joint="left_hip_pitch_joint" />
    <motor name="left_hip_roll_joint_ctrl" joint="left_hip_roll_joint"  />
    <motor name="left_hip_yaw_joint_ctrl" joint="left_hip_yaw_joint"  />
    <motor name="left_knee_joint_ctrl" joint="left_knee_joint"  />
    <motor name="left_foot1_joint_ctrl" joint="left_foot1_joint"  />
    <motor name="left_foot2_joint_ctrl" joint="left_foot2_joint"  />
    <motor name="right_hip_pitch_joint_ctrl" joint="right_hip_pitch_joint"  />
    <motor name="right_hip_roll_joint_ctrl" joint="right_hip_roll_joint"  />
    <motor name="right_hip_yaw_joint_ctrl" joint="right_hip_yaw_joint"  />
    <motor name="right_knee_joint_ctrl" joint="right_knee_joint"  />
    <motor name="right_foot1_joint_ctrl" joint="right_foot1_joint"  />
    <motor name="right_foot2_joint_ctrl" joint="right_foot2_joint"  />
  </actuator>

  <contact>
    <exclude body1="pelvis_link" body2="left_hip_pitch_link" />
    <exclude body1="left_hip_pitch_link" body2="left_hip_roll_link" />
    <exclude body1="left_hip_roll_link" body2="left_hip_yaw_link" />
    <exclude body1="left_hip_yaw_link" body2="left_knee_link" />
    <exclude body1="left_knee_link" body2="left_foot1_link" />
    <exclude body1="left_foot1_link" body2="left_foot2_link" />
    <exclude body1="pelvis_link" body2="right_hip_pitch_link" />
    <exclude body1="right_hip_pitch_link" body2="right_hip_roll_link" />
    <exclude body1="right_hip_roll_link" body2="right_hip_yaw_link" />
    <exclude body1="right_hip_yaw_link" body2="right_knee_link" />
    <exclude body1="right_knee_link" body2="right_foot1_link" />
    <exclude body1="right_foot1_link" body2="right_foot2_link" />
  </contact>




  <sensor>
    <gyro name="imu_ang_vel" site="imu_in_pelvis"/>
    <velocimeter name="imu_lin_vel" site="imu_in_pelvis"/>
    <framequat name="imu_quat" objtype="site" objname="imu_in_pelvis"/>
    <subtreeangmom name="root_angmom" body="pelvis_link"/>
  </sensor>

  <visual>
    <headlight diffuse="0.6 0.6 0.6" ambient="0.1 0.1 0.1" specular="0.9 0.9 0.9"/>
    <rgba haze="0.15 0.25 0.35 1"/>
    <global azimuth="-140" elevation="-20"/>
  </visual>


</mujoco>